Traceback (most recent call last):
  File "/Users/kristian/miniforge3/envs/tf_M1/lib/python3.10/site-packages/jupyter_cache/executors/utils.py", line 58, in single_nb_execution
    executenb(
  File "/Users/kristian/miniforge3/envs/tf_M1/lib/python3.10/site-packages/nbclient/client.py", line 1263, in execute
    return NotebookClient(nb=nb, resources=resources, km=km, **kwargs).execute()
  File "/Users/kristian/miniforge3/envs/tf_M1/lib/python3.10/site-packages/nbclient/util.py", line 85, in wrapped
    return just_run(coro(*args, **kwargs))
  File "/Users/kristian/miniforge3/envs/tf_M1/lib/python3.10/site-packages/nbclient/util.py", line 60, in just_run
    return loop.run_until_complete(coro)
  File "/Users/kristian/miniforge3/envs/tf_M1/lib/python3.10/asyncio/base_events.py", line 646, in run_until_complete
    return future.result()
  File "/Users/kristian/miniforge3/envs/tf_M1/lib/python3.10/site-packages/nbclient/client.py", line 701, in async_execute
    await self.async_execute_cell(
  File "/Users/kristian/miniforge3/envs/tf_M1/lib/python3.10/site-packages/nbclient/client.py", line 1019, in async_execute_cell
    await self._check_raise_for_error(cell, cell_index, exec_reply)
  File "/Users/kristian/miniforge3/envs/tf_M1/lib/python3.10/site-packages/nbclient/client.py", line 913, in _check_raise_for_error
    raise CellExecutionError.from_cell_and_msg(cell, exec_reply_content)
nbclient.exceptions.CellExecutionError: An error occurred while executing the following cell:
------------------
# Connecting to Cassandra
from cassandra.cluster import Cluster
cluster = Cluster(['localhost'], port=9042)
session = cluster.connect()
------------------

[0;31m---------------------------------------------------------------------------[0m
[0;31mImportError[0m                               Traceback (most recent call last)
Cell [0;32mIn [1], line 2[0m
[1;32m      1[0m [38;5;66;03m# Connecting to Cassandra[39;00m
[0;32m----> 2[0m [38;5;28;01mfrom[39;00m [38;5;21;01mcassandra[39;00m[38;5;21;01m.[39;00m[38;5;21;01mcluster[39;00m [38;5;28;01mimport[39;00m Cluster
[1;32m      3[0m cluster [38;5;241m=[39m Cluster([[38;5;124m'[39m[38;5;124mlocalhost[39m[38;5;124m'[39m], port[38;5;241m=[39m[38;5;241m9042[39m)
[1;32m      4[0m session [38;5;241m=[39m cluster[38;5;241m.[39mconnect()

[0;31mImportError[0m: dlopen(/Users/kristian/miniforge3/envs/tf_M1/lib/python3.10/site-packages/cassandra/cluster.cpython-310-darwin.so, 0x0002): tried: '/Users/kristian/miniforge3/envs/tf_M1/lib/python3.10/site-packages/cassandra/cluster.cpython-310-darwin.so' (mach-o file, but is an incompatible architecture (have 'x86_64', need 'arm64')), '/System/Volumes/Preboot/Cryptexes/OS/Users/kristian/miniforge3/envs/tf_M1/lib/python3.10/site-packages/cassandra/cluster.cpython-310-darwin.so' (no such file), '/Users/kristian/miniforge3/envs/tf_M1/lib/python3.10/site-packages/cassandra/cluster.cpython-310-darwin.so' (mach-o file, but is an incompatible architecture (have 'x86_64', need 'arm64'))
ImportError: dlopen(/Users/kristian/miniforge3/envs/tf_M1/lib/python3.10/site-packages/cassandra/cluster.cpython-310-darwin.so, 0x0002): tried: '/Users/kristian/miniforge3/envs/tf_M1/lib/python3.10/site-packages/cassandra/cluster.cpython-310-darwin.so' (mach-o file, but is an incompatible architecture (have 'x86_64', need 'arm64')), '/System/Volumes/Preboot/Cryptexes/OS/Users/kristian/miniforge3/envs/tf_M1/lib/python3.10/site-packages/cassandra/cluster.cpython-310-darwin.so' (no such file), '/Users/kristian/miniforge3/envs/tf_M1/lib/python3.10/site-packages/cassandra/cluster.cpython-310-darwin.so' (mach-o file, but is an incompatible architecture (have 'x86_64', need 'arm64'))

